<robot name="RRR">    

    <link name = "Link1">
		<visual>
            <geometry>
                <cylinder length="1" radius="0.025" />
            </geometry> 
            <material name = "base">
                <color rgba="0 1 0 1" />
            </material>
            <origin xyz="0 0 0.5"/>
        </visual>
        <visual>
            <geometry>
                <cylinder length="0.05" radius="0.035" />
            </geometry>
            <material name="rot">
                <color rgba="1 0 0 1" />
            </material>
            <origin xyz="0 0 1"  rpy="0 0 1.57" />
        </visual>
        <inertial>
            <origin xyz="0 0 0" rpy="0 0 0" />
            <mass value="0" />
            <inertia ixx="0" ixy="0" ixz="0" iyy="0" iyz="0" izz="0"/>
        </inertial>
    </link>

    <link name = "Link2">
        <visual>
            <origin xyz="0.6 0 0" rpy= "0 1.57 0" />
            <geometry>
                <cylinder length="1.2" radius="0.02"/>
            </geometry> 
            <material name = "rot">
                <color rgba="1 0 0 1" />
            </material>
        </visual>
        <visual>
            <origin xyz="1.2 0 0" rpy="1.57 0 0" />
            <geometry>
                <cylinder length="0.05" radius="0.035" />
            </geometry>
            <material name="rot">
                <color rgba="1 0 0 1" />
            </material>
        </visual>
        <inertial>
            <origin xyz="0 0 0" rpy="0 0 0" />
            <mass value="0" />
            <inertia ixx="0" ixy="0" ixz="0" iyy="0" iyz="0" izz="0"/>
        </inertial>
    </link>

    <link name = "Link3">
	    <visual>
            <origin xyz="1 0 0" rpy="0 1.57 0" />
            <geometry>
                <cylinder length="2" radius="0.015" />
            </geometry> 
            <material name = "rot">
                <color rgba="0 0 1 1" />
            </material>
        </visual>
        <visual>
            <origin xyz="2 0 0" rpy="0 0 1.57" />
            <geometry>
                <cylinder length="0.05" radius="0.035" />
            </geometry>
            <material name="rot">
                <color rgba="1 0 0 1" />
            </material>
        </visual>
        <inertial>
            <origin xyz="0 0 0" rpy="0 0 0" />
            <mass value="0" />
            <inertia ixx="0" ixy="0" ixz="0" iyy="0" iyz="0" izz="0"/>
        </inertial>
    </link>

    <link name = "Link4">
		<visual>
            <origin xyz="1.85 0 0" rpy="0 1.57 0" />
            <geometry>
                <cylinder length="3.7" radius="0.01" />
            </geometry> 
            <material name = "rot">
                <color rgba="1 0 0 1" />
            </material>
        </visual>
        <inertial>
            <origin xyz="0 0 0" rpy="0 0 0" />
            <mass value="0" />
            <inertia ixx="0" ixy="0" ixz="0" iyy="0" iyz="0" izz="0"/>
        </inertial>
    </link>

    <link name="ee" />

    <joint name = "Joint1" type="revolute">
        <parent link = "Link1" />
        <child link = "Link2" />
        <origin xyz = "0 0 1" rpy="0 0 1.57"/>
        <axis xyz = "0 0 1" />
        <limit lower = "-3.14" upper = "3.14" effort = "0" velocity = "1" />
        <dynamics damping="0.0" friction="0.0"/>
    </joint>

    <joint name = "Joint2" type="revolute">
        <parent link = "Link2" />
        <child link = "Link3" />
        <origin xyz = "1.2 0 0" rpy="1.57 0 0"/>
        <axis xyz = "0 0 1" />
        <limit lower = "-3.14" upper = "3.14" effort = "0" velocity = "1"/>
        <dynamics damping="0.0" friction="0.0"/>
    </joint>


    <joint name = "Joint3" type="revolute">
        <parent link = "Link3" />
        <child link = "Link4" />
        <origin xyz = "2 0 0" rpy = "0 0 0"/>
        <axis xyz = "0 0 1" />
        <limit lower = "-3.14" upper = "3.14" effort = "0" velocity = "1" />
        <dynamics damping="0.0" friction="0.0"/>
    </joint>

    <joint name="ee_joint" type="fixed">
        <parent link = "Link4" />
        <child link = "ee" />
        <origin xyz="3.7 0 0" rpy="0 0 0" />
    </joint>


</robot>
