<robot name="RRR">    

    <link name = "Link1">
        <inertial>
            <origin xyz="0 0 0" rpy="0 0 0" />
            <mass value="0" />
            <inertia ixx="0" ixy="0" ixz="0" iyy="0" iyz="0" izz="0"/>
        </inertial>
    </link>

    <link name = "Link2">
        <inertial>
            <origin xyz="0 0 0" rpy="0 0 0" />
            <mass value="0" />
            <inertia ixx="0" ixy="0" ixz="0" iyy="0" iyz="0" izz="0"/>
        </inertial>
    </link>

    <link name = "Link3">
        <inertial>
            <origin xyz="0 0 0" rpy="0 0 0" />
            <mass value="0" />
            <inertia ixx="0" ixy="0" ixz="0" iyy="0" iyz="0" izz="0"/>
        </inertial>
    </link>

    <link name = "Link4">
        <inertial>
            <origin xyz="0 0 0" rpy="0 0 0" />
            <mass value="0" />
            <inertia ixx="0" ixy="0" ixz="0" iyy="0" iyz="0" izz="0"/>
        </inertial>
    </link>

    <link name="ee" />

    <joint name = "Joint1" type="revolute">
        <parent link = "Link1" />
        <child link = "Link2" />
        <origin xyz = "0 0 1" rpy="0 0 1.57"/>
        <axis xyz = "0 0 1" />
        <limit lower = "-3.14" upper = "3.14" effort = "0" velocity = "1" />
        <dynamics damping="0.0" friction="0.0"/>
    </joint>

    <joint name = "Joint2" type="revolute">
        <parent link = "Link2" />
        <child link = "Link3" />
        <origin xyz = "1.2 0 0" rpy="1.57 0 0"/>
        <axis xyz = "0 0 1" />
        <limit lower = "-3.14" upper = "3.14" effort = "0" velocity = "1"/>
        <dynamics damping="0.0" friction="0.0"/>
    </joint>


    <joint name = "Joint3" type="revolute">
        <parent link = "Link3" />
        <child link = "Link4" />
        <origin xyz = "2 0 0" rpy = "0 0 0"/>
        <axis xyz = "0 0 1" />
        <limit lower = "-3.14" upper = "3.14" effort = "0" velocity = "1" />
        <dynamics damping="0.0" friction="0.0"/>
    </joint>

    <joint name="ee_joint" type="fixed">
        <parent link = "Link4" />
        <child link = "ee" />
        <origin xyz="3.7 0 0" rpy="0 0 0" />
    </joint>


</robot>
